inst/extdata/sample.txt
type,time,id,price,size,type
A,30134030,727589,11.48,400,BID
A,29096183,485866,11.2,100,BID
A,30606932,920091,11.12,2200,BID
A,25801147,52109,11.03,1500,BID
A,29045306,477140,10.7,300,BID
A,27000227,174193,9.95,100,BID
A,27000239,174230,0.01,100,BID
A,27618133,265396,0.01,100,BID
A,30553223,883987,11.54,200,ASK
A,30553226,883990,11.56,200,ASK
A,28867037,446857,11.62,300,ASK
A,30606943,920100,11.89,2000,ASK
A,30090894,710107,11.98,300,ASK
A,25502076,23751,12,100,ASK
A,28609262,404400,12.27,500,ASK
A,28806070,437134,13.74,2320,ASK
A,28904921,454042,15.5,25,ASK
A,27000057,173314,18.41,500,ASK
A,27000069,173348,19.41,500,ASK
A,28940634,458060,22.5,10,ASK
A,28500201,390292,101.7,100,ASK
A,27618133,265397,2000,100,ASK
T,30553221,265397,11.54,300
C,30641234,883990
A,30641235,939267,11.53,200,ASK
C,30671235,939267
C,30681263,727589
T,30681263,727589,11.48,400
C,30681264,883987
A,30681264,961948,11.48,300,ASK
A,30681265,961949,11.53,200,ASK
C,30681267,961949
A,30786109,1005832,11.3,5000,BID
A,30844846,1029945,11.53,100,ASK
C,30962295,961948
A,31069366,1112665,11.32,100,BID
A,31069380,1112675,11.5,100,ASK
C,31099380,1112675
A,31285893,1231884,11.49,200,ASK
R,31295779,1231884,150
T,31295779,1231884,11.49,50
C,31295781,1231884
A,31295784,1237001,11.49,700,ASK
A,31295786,1237002,11.46,100,ASK
C,31297044,1237002
A,31297045,1237990,11.45,100,ASK
C,31325785,1237001
A,31532894,1393366,11.35,1000,BID
C,31534572,1112665
C,31596167,1237990
T,31596167,1237990,11.45,100
A,31596168,1427375,11.41,200,BID
A,31596168,1427376,11.49,200,ASK
C,31626168,1427375
C,31626169,1427376
A,31626170,1437591,11.41,200,BID
C,31656170,1437591
A,31656171,1445603,11.49,200,ASK
C,31679038,485866
A,31679039,1464321,11.43,100,BID
C,31686171,1445603
A,31686172,1469298,11.41,200,BID
C,31691058,1469298
A,31691059,1471001,11.49,200,ASK
C,31721059,1471001
A,31721060,1485913,11.43,200,BID
C,31751061,1485913
A,31773862,1519380,11.51,100,ASK
C,31803862,1519380
A,31863655,1566228,11.46,100,BID
C,31863669,1566228
T,31863669,1566228,11.46,100
A,31863671,1566272,11.49,100,ASK
C,31893671,1566272
A,31914795,1599001,11.49,100,ASK
C,31944795,1599001
A,31995652,1640233,11.96,100,ASK
A,32030517,1672249,16,100,ASK
A,32088962,1717481,11.41,200,BID
A,32088963,1717482,11.51,100,ASK
C,32088963,1717481
A,32089006,1717520,11.44,100,ASK
C,32095898,1717520
C,32095923,1464321
T,32095923,1464321,11.43,100
A,32095946,1720502,11.43,100,ASK
C,32095964,1717482
C,32099089,1720502
A,32099090,1721536,11.49,100,ASK
A,32099093,1721540,11.33,200,BID
C,32129090,1721536
C,32129093,1721540
A,32285251,1836322,11.37,100,BID
A,32285251,1836323,11.5,200,ASK
C,32315251,1836322
C,32315251,1836323
A,32381937,1895332,11.37,100,BID
A,32381937,1895333,11.5,200,ASK
C,32411937,1895332
C,32411937,1895333
A,32450239,1945296,11.37,100,BID
A,32450239,1945297,11.51,100,ASK
C,32480239,1945296
C,32480239,1945297
A,32480241,1958251,11.38,200,BID
A,32480241,1958252,11.51,100,ASK
C,32510241,1958251
C,32510241,1958252
A,32559277,2002767,11.48,100,ASK
R,32673729,2002767,50
T,32673729,2002767,11.48,50
A,32673730,2042908,11.48,100,ASK
A,32980635,2220230,11.36,1000,BID
C,32980683,2220230
A,32980780,2220372,11.36,1000,BID
C,32980913,2220372
C,33015998,2002767
T,33015998,2002767,11.48,50
A,33071741,2264148,11.36,500,BID
C,33071791,2264148
A,33072005,2264289,11.36,500,BID
C,33080835,2264289
A,33094076,2275261,11.44,2500,ASK
A,33214907,2340568,11.41,500,BID
C,33220606,2275261
A,33220607,2342766,11.47,200,ASK
A,33241697,2353914,11.44,500,BID
A,33268793,2373475,11.44,1500,BID
C,33278515,2342766
C,33300696,2353914
C,33300792,2373475
C,33300907,2340568
A,33300908,2409455,11.36,300,BID
C,33300912,2409455
A,33322172,2429245,11.33,200,BID
A,33322173,2429246,11.5,200,ASK
C,33352172,2429245
C,33352172,2429246
C,33435839,2042908
A,33435940,2525691,11.48,100,ASK
A,33666557,2660904,11.48,100,ASK
C,33671649,2660904
A,33671682,2663034,11.48,600,ASK
A,33730245,2695572,11.38,300,BID
C,33892808,446857
A,33892812,2804135,11.57,300,ASK
A,33900291,2812008,11.47,100,ASK
C,33901109,1005832
A,33901217,2817638,11.26,100,BID
A,33901218,2817643,19.21,100,ASK
A,33903163,2826600,11.34,100,BID
A,33903163,2826601,12.25,100,ASK
A,33904732,2834382,11.2,100,BID
A,33904732,2834383,15.5,100,ASK
C,33907384,2812008
A,33908581,2854766,0.01,100,BID
A,33908582,2854767,199999.99,100,ASK
A,33910316,2864029,10,100,BID
A,33910316,2864030,20,100,ASK
A,33911688,2870595,1,100,BID
A,33911689,2870596,100,100,ASK
A,33911700,2870654,1.00E-04,100,BID
A,33911700,2870655,199999.99,100,ASK
A,33912200,2873240,1.00E-04,100,BID
A,33912200,2873241,199999.99,100,ASK
A,33912522,2874987,11.33,100,BID
A,33912523,2874988,19.42,100,ASK
A,33913617,2880457,0.01,100,BID
A,33913617,2880458,199999.99,100,ASK
A,33913813,2881339,0.01,100,BID
A,33913813,2881340,199999.99,100,ASK
A,33915107,2887526,11.04,100,BID
A,33915107,2887527,12.63,100,ASK
A,33915158,2887800,0.01,100,BID
A,33915158,2887801,199999.99,100,ASK
A,33915632,2890088,1.00E-04,100,BID
A,33915632,2890089,199999.99,100,ASK
A,33918478,2904315,1.00E-04,100,BID
A,33918478,2904316,199999.99,100,ASK
A,33919394,2908726,11.44,100,BID
A,33919395,2908727,18.99,100,ASK
A,33919699,2910292,1.00E-04,100,BID
A,33919699,2910293,199999.99,100,ASK
A,33920685,2915285,1.00E-04,100,BID
A,33920685,2915286,199000,100,ASK
A,33921340,2918637,0.01,100,BID
A,33921340,2918638,199999.99,100,ASK
A,33921613,2920021,11.38,100,BID
A,33921613,2920022,13.51,100,ASK
A,33922628,2926511,11.25,100,BID
A,33922629,2926512,17,100,ASK
A,33922650,2926631,11.34,100,BID
A,33922650,2926632,12.37,100,ASK
A,33923255,2929559,2.8,100,BID
A,33923255,2929560,19.15,100,ASK
A,33923416,2930368,8.06,100,BID
A,33923417,2930369,13.58,100,ASK
A,33926315,2944894,8,100,BID
A,33926315,2944895,18.75,100,ASK
A,33927743,2952250,0.01,100,BID
A,33927743,2952251,199999.99,100,ASK
A,33928040,2953716,11.33,100,BID
A,33928040,2953717,12.33,100,ASK
A,33929103,2962228,1.00E-04,100,BID
A,33929103,2962229,199999.99,100,ASK
C,33930277,390292
A,33930277,2970172,86.46,100,ASK
A,33931191,2976038,0.01,100,BID
A,33931191,2976041,199999.98,100,ASK
A,33932699,2985077,11.24,100,BID
A,33932700,2985078,13.23,100,ASK
A,33933652,2990551,11.25,100,BID
A,33933652,2990552,18.43,100,ASK
A,33934649,2996423,10.9,100,BID
A,33934649,2996425,19.05,100,ASK
A,33937040,3012721,2,100,BID
A,33937040,3012722,27.9,100,ASK
A,33938328,3020463,10,100,BID
A,33938328,3020464,20,100,ASK
A,33938343,3020548,11.25,100,BID
A,33938343,3020549,18.5,100,ASK
A,33938426,3021017,10.68,100,BID
A,33938426,3021018,18.74,100,ASK
A,33938547,3021761,8,100,BID
A,33938547,3021762,32,100,ASK
A,33939098,3024765,1.00E-04,100,BID
A,33939099,3024766,199999.99,100,ASK
A,33939327,3026054,5,100,BID
A,33939328,3026055,25,100,ASK
A,33939959,3029818,11.4,100,BID
A,33939960,3029819,19.38,100,ASK
A,33940772,3034418,9.75,100,BID
A,33940772,3034419,17.25,100,ASK
A,33941097,3036098,1.00E-04,100,BID
A,33941097,3036099,199999.99,100,ASK
A,33941573,3038836,7,100,BID
A,33941573,3038837,42,100,ASK
A,33943120,3047721,1.00E-04,100,BID
A,33943120,3047722,199999.99,100,ASK
A,33945558,3063823,1.00E-04,100,BID
A,33945559,3063824,199999.99,100,ASK
A,33946537,3070237,3,100,BID
A,33946537,3070238,19,100,ASK
A,33948055,3079716,11.05,100,BID
A,33948055,3079717,12.5,100,ASK
A,33948201,3080607,8.77,100,BID
A,33948201,3080608,17.15,100,ASK
A,33949574,3089253,5,100,BID
A,33949574,3089254,33,100,ASK
A,33951808,3101762,11.26,100,BID
A,33951808,3101763,13.78,100,ASK
A,33952254,3104335,7.47,100,BID
A,33952254,3104336,15.53,100,ASK
A,33952428,3105309,11.3,100,BID
A,33952428,3105310,11.6,100,ASK
A,33954779,3118954,11.25,100,BID
A,33954779,3118955,19.15,100,ASK
A,33955356,3122246,1.00E-04,100,BID
A,33955356,3122248,199999.99,100,ASK
A,33956276,3127480,0.01,100,BID
A,33956276,3127481,199999.99,100,ASK
A,33956445,3128408,1.00E-04,100,BID
A,33956446,3128409,199999.99,100,ASK
A,33956814,3130488,0.01,100,BID
A,33956814,3130489,199999.99,100,ASK
A,33957194,3132578,11.56,100,ASK
A,33957851,3136432,1,100,BID
A,33957851,3136433,13.92,100,ASK
A,33958134,3138167,1.00E-04,100,BID
